<!-- 

Sarcomere Dynamics Software License Notice
- - - - - - - - - - - - - - - - - - - - - -
This software is developed by Sarcomere Dynamics Inc. for use with the ARTUS family of robotic products,
including ARTUS Lite, ARTUS+, ARTUS Dex, and Hyperion.

Copyright (c) 2023–2025, Sarcomere Dynamics Inc. All rights reserved.

Licensed under the Sarcomere Dynamics Software License.
See the LICENSE file in the repository for full details.
-->


<robot name="ArtusLite_LeftHand">
<link name="left_forearm_and_palm_assembly">
<visual>
<origin xyz="6.6271857793176427714e-18 0.1062500000000000111 0.00092800153782069891295" rpy="1.570796326794896558 -3.8857805861880478915e-16 -3.141592653589793116" />
<geometry>
<mesh filename="meshes/base_plate.stl"/>
</geometry>
<material name="base_plate_material">
<color rgba="0.91764705882352937127 0.91764705882352937127 0.91764705882352937127 1.0"/>
</material>
</visual>
<collision>
<origin xyz="6.6271857793176427714e-18 0.1062500000000000111 0.00092800153782069891295" rpy="1.570796326794896558 -3.8857805861880478915e-16 -3.141592653589793116" />
<geometry>
<mesh filename="meshes/base_plate.stl"/>
</geometry>
</collision>
<visual>
<origin xyz="1.3537373440378462788e-17 0.10624999999999999722 0.0009280015378206921909" rpy="1.570796326794896558 -3.8857805861880478915e-16 -3.141592653589793116" />
<geometry>
<mesh filename="meshes/forearm_urdf_2.stl"/>
</geometry>
<material name="forearm_urdf_2_material">
<color rgba="0.91764705882352937127 0.91764705882352937127 0.91764705882352937127 1.0"/>
</material>
</visual>
<collision>
<origin xyz="1.3537373440378462788e-17 0.10624999999999999722 0.0009280015378206921909" rpy="1.570796326794896558 -3.8857805861880478915e-16 -3.141592653589793116" />
<geometry>
<mesh filename="meshes/forearm_urdf_2.stl"/>
</geometry>
</collision>
<visual>
<origin xyz="0.09323237591646159339 0.14039834978141410571 0.02470000000000002402" rpy="-1.9428902930940239457e-16 -6.1987452208277741029e-16 3.141592653589793116" />
<geometry>
<mesh filename="meshes/left_palm_urdf.stl"/>
</geometry>
<material name="left_palm_urdf_material">
<color rgba="0.34901960784313723618 0.37647058823529411242 0.4000000000000000222 1.0"/>
</material>
</visual>
<collision>
<origin xyz="0.09323237591646159339 0.14039834978141410571 0.02470000000000002402" rpy="-1.9428902930940239457e-16 -6.1987452208277741029e-16 3.141592653589793116" />
<geometry>
<mesh filename="meshes/left_palm_urdf.stl"/>
</geometry>
</collision>
<inertial>
<origin xyz="-5.9108357083818315178e-05 0.091404025280533082731 -0.0013154474645475043842" rpy="0 0 0"/>
<mass value="0.6183233699126555738" />
<inertia ixx="0.0026873071213010506914" ixy="-3.5682943012256891459e-06"  ixz="-6.8536554982644566593e-06" iyy="0.00062243146941740317302" iyz="8.7532039777069416478e-05" izz="0.0027237114853027382874" />
</inertial>
</link>

<link name="t4_urdf">
<visual>
<origin xyz="-0.083900000000000002354 1.7347234759768070944e-17 -0.0097499999999999809042" rpy="3.141592653589793116 3.1778737969816739036e-18 2.3981537860382147468e-17" />
<geometry>
<mesh filename="meshes/t4_urdf.stl"/>
</geometry>
<material name="t4_urdf_material">
<color rgba="0.34901960784313723618 0.37647058823529411242 0.4000000000000000222 1.0"/>
</material>
</visual>
<collision>
<origin xyz="-0.083900000000000002354 1.7347234759768070944e-17 -0.0097499999999999809042" rpy="3.141592653589793116 3.1778737969816739036e-18 2.3981537860382147468e-17" />
<geometry>
<mesh filename="meshes/t4_urdf.stl"/>
</geometry>
</collision>
<inertial>
<origin xyz="-0.0058427530488761036942 -3.1276186539081817748e-10 -0.010494198053015347041" rpy="0 0 0"/>
<mass value="0.010288104754589431911" />
<inertia ixx="9.0136774732367771637e-07" ixy="-8.7726063786385211324e-14"  ixz="1.6540276525723776845e-08" iyy="9.0496845343764967793e-07" iyz="-2.453532247916277141e-12" izz="1.1625687816350763315e-06" />
</inertial>
</link>

<link name="t3_urdf">
<visual>
<origin xyz="-0.067374999999999990452 -7.5000000000019495516e-05 -0.0087500000000000476702" rpy="-1.5707963267948976682 -5.5985074572889039722e-16 1.5483429638934714785e-17" />
<geometry>
<mesh filename="meshes/t3_urdf.stl"/>
</geometry>
<material name="t3_urdf_material">
<color rgba="0.34901960784313723618 0.37647058823529411242 0.4000000000000000222 1.0"/>
</material>
</visual>
<collision>
<origin xyz="-0.067374999999999990452 -7.5000000000019495516e-05 -0.0087500000000000476702" rpy="-1.5707963267948976682 -5.5985074572889039722e-16 1.5483429638934714785e-17" />
<geometry>
<mesh filename="meshes/t3_urdf.stl"/>
</geometry>
</collision>
<inertial>
<origin xyz="-0.00088723630070686176907 -0.014545467252332650726 -0.0087499987535804343158" rpy="0 0 0"/>
<mass value="0.030585609045160676994" />
<inertia ixx="6.3609316339689915345e-06" ixy="1.7049934843751148488e-07"  ixz="-5.4125620474234134574e-13" iyy="2.2394270317379842441e-06" iyz="4.5912259839849730529e-13" izz="6.4143771252919373982e-06" />
</inertial>
</link>

<link name="t2_urdf">
<visual>
<origin xyz="-0.067450000000000023825 0.040300000000000030242 -0.0072500000000000931755" rpy="-1.570796326794896558 -1.5925779166409607626e-15 4.1799615988450532947e-17" />
<geometry>
<mesh filename="meshes/t2_urdf.stl"/>
</geometry>
<material name="t2_urdf_material">
<color rgba="0.34901960784313723618 0.37647058823529411242 0.4000000000000000222 1.0"/>
</material>
</visual>
<collision>
<origin xyz="-0.067450000000000023825 0.040300000000000030242 -0.0072500000000000931755" rpy="-1.570796326794896558 -1.5925779166409607626e-15 4.1799615988450532947e-17" />
<geometry>
<mesh filename="meshes/t2_urdf.stl"/>
</geometry>
</collision>
<inertial>
<origin xyz="0.0091415418957211669326 -0.0010488393377384996885 -0.0072499940743799918055" rpy="0 0 0"/>
<mass value="0.014650153995995354728" />
<inertia ixx="7.8231186604362120536e-07" ixy="-1.0095612977356357154e-07"  ixz="-1.4446714799319650799e-13" iyy="1.7012075450947944876e-06" iyz="1.9146541636642769121e-13" izz="1.7152649221519824158e-06" />
</inertial>
</link>

<link name="t1_urdf">
<visual>
<origin xyz="-0.094450000000000020051 0.040300000000000002487 -0.0062500000000000055511" rpy="-1.5707963267948961139 -8.9533720009632975891e-16 -4.1541671986217826162e-17" />
<geometry>
<mesh filename="meshes/t1_urdf.stl"/>
</geometry>
<material name="t1_urdf_material">
<color rgba="0.34901960784313723618 0.37647058823529411242 0.4000000000000000222 1.0"/>
</material>
</visual>
<collision>
<origin xyz="-0.094450000000000020051 0.040300000000000002487 -0.0062500000000000055511" rpy="-1.5707963267948961139 -8.9533720009632975891e-16 -4.1541671986217826162e-17" />
<geometry>
<mesh filename="meshes/t1_urdf.stl"/>
</geometry>
</collision>
<inertial>
<origin xyz="0.0010824005610924891663 0.010114885903667096556 -0.0062499582332070317131" rpy="0 0 0"/>
<mass value="0.011648615104359208092" />
<inertia ixx="1.0781644849112865646e-06" ixy="2.8463521071749681553e-08"  ixz="-2.6682779572601763978e-12" iyy="4.5092952838927327113e-07" iyz="-5.6995504514253930883e-12" izz="1.1054367169332249318e-06" />
</inertial>
</link>

<joint name="thumb_34" type="revolute">
<origin xyz="0.02699999999999996847 1.3877787807814456755e-17 -0.0010000000000000008882" rpy="9.5863578907522161675e-16 7.0789471869755460379e-15 -1.57079632679489678" />
<parent link="t2_urdf" />
<child link="t1_urdf" />
<axis xyz="0 0 1"/>
<limit effort="1000" velocity="20" lower="0" upper="1.570796326794896558"/>
<joint_properties friction="0.0"/>
</joint>

<joint name="thumb_23" type="revolute">
<origin xyz="7.5000000000019495516e-05 -0.040375000000000021982 -0.0014999999999999770461" rpy="4.3531037203976025557e-16 9.2334020849442836759e-15 -1.570796326794896558" />
<parent link="t3_urdf" />
<child link="t2_urdf" />
<axis xyz="0 0 1"/>
<limit effort="1000" velocity="20" lower="0" upper="1.570796326794896558"/>
<joint_properties friction="0.0"/>
</joint>

<joint name="thumb_12" type="revolute">
<origin xyz="-0.016524999999999977207 0.008750000000000030323 -0.0098250000000000003997" rpy="-1.5707963267948956698 -1.2740903539558106061 3.0516010405355311794e-15" />
<parent link="t4_urdf" />
<child link="t3_urdf" />
<axis xyz="0 0 1"/>
<limit effort="1000" velocity="20" lower="0.29670597283903604735" upper="1.570796326794896558"/>
<joint_properties friction="0.0"/>
</joint>

<joint name="thumb_01" type="revolute">
<origin xyz="0.014293519578924870905 0.14573355735843290804 -0.026000647022553280419" rpy="1.5707963267948958919 -0.79305228016610029851 -2.9670597283903594743" />
<parent link="left_forearm_and_palm_assembly" />
<child link="t4_urdf" />
<axis xyz="0 0 1"/>
<limit effort="1000" velocity="20" lower="-0.785398163397448279" upper="0.785398163397448279"/>
<joint_properties friction="0.0"/>
</joint>

<link name="d4_1_urdf">
<visual>
<origin xyz="-0.079149999999999970379 0 -0.0087500000000000008327" rpy="-3.141592653589793116 2.1897057982959596107e-18 -3.614489769532107713e-18" />
<geometry>
<mesh filename="meshes/d4-1_urdf.stl"/>
</geometry>
<material name="d4-1_urdf_material">
<color rgba="0.34901960784313723618 0.37647058823529411242 0.4000000000000000222 1.0"/>
</material>
</visual>
<collision>
<origin xyz="-0.079149999999999970379 0 -0.0087500000000000008327" rpy="-3.141592653589793116 2.1897057982959596107e-18 -3.614489769532107713e-18" />
<geometry>
<mesh filename="meshes/d4-1_urdf.stl"/>
</geometry>
</collision>
<inertial>
<origin xyz="-0.0062842813664121394135 2.5879353762553803068e-10 -0.0081923602347070741819" rpy="0 0 0"/>
<mass value="0.007132231448786834245" />
<inertia ixx="4.8911025414963878454e-07" ixy="-2.0479711681204754417e-14"  ixz="1.4355227474224370408e-08" iyy="5.4026894403887874679e-07" iyz="1.562506849345440705e-13" izz="7.1745332239577899243e-07" />
</inertial>
</link>

<link name="d3_1_urdf">
<visual>
<origin xyz="-0.063875000000000015099 0.0010000000000000286438 -0.0072500000000000515421" rpy="-1.5707963267948976682 -5.8164777328800134424e-16 -6.5141947025538285768e-19" />
<geometry>
<mesh filename="meshes/d3-1_urdf.stl"/>
</geometry>
<material name="d3-1_urdf_material">
<color rgba="0.34901960784313723618 0.37647058823529411242 0.4000000000000000222 1.0"/>
</material>
</visual>
<collision>
<origin xyz="-0.063875000000000015099 0.0010000000000000286438 -0.0072500000000000515421" rpy="-1.5707963267948976682 -5.8164777328800134424e-16 -6.5141947025538285768e-19" />
<geometry>
<mesh filename="meshes/d3-1_urdf.stl"/>
</geometry>
</collision>
<inertial>
<origin xyz="-0.00069598131543222030437 -0.013461728376310289415 -0.0072499999060333126383" rpy="0 0 0"/>
<mass value="0.022614819883081289931" />
<inertia ixx="4.0178611346719698098e-06" ixy="1.0347442960778389722e-07"  ixz="1.2277302998276793688e-14" iyy="1.3431972486149210183e-06" iyz="-4.2659478127328136664e-14" izz="4.0893383736853743102e-06" />
</inertial>
</link>

<link name="d2_1_urdf">
<visual>
<origin xyz="-0.062875000000000041966 0.038875000000000006772 -0.0067500000000000996703" rpy="-1.57079632679489678 -1.6053990316121190964e-15 3.7644346845707085966e-19" />
<geometry>
<mesh filename="meshes/d2-1_urdf.stl"/>
</geometry>
<material name="d2-1_urdf_material">
<color rgba="0.34901960784313723618 0.37647058823529411242 0.4000000000000000222 1.0"/>
</material>
</visual>
<collision>
<origin xyz="-0.062875000000000041966 0.038875000000000006772 -0.0067500000000000996703" rpy="-1.57079632679489678 -1.6053990316121190964e-15 3.7644346845707085966e-19" />
<geometry>
<mesh filename="meshes/d2-1_urdf.stl"/>
</geometry>
</collision>
<inertial>
<origin xyz="0.0084939436722219485709 -0.00026229267814973505901 -0.0067499976398635698829" rpy="0 0 0"/>
<mass value="0.011864989574403404446" />
<inertia ixx="5.4043476975389846272e-07" ixy="-5.868659804644187575e-08"  ixz="4.1185672862648097616e-14" iyy="1.2212373681397833892e-06" iyz="1.4027739153132486104e-13" izz="1.1986582767035206919e-06" />
</inertial>
</link>

<link name="d1_1_urdf">
<visual>
<origin xyz="-0.088875000000000023426 0.038874999999999992895 -0.0062500000000000159595" rpy="-1.5707963267948961139 -8.911581877347044605e-16 -2.9411789633500253405e-19" />
<geometry>
<mesh filename="meshes/d1-1_urdf.stl"/>
</geometry>
<material name="d1-1_urdf_material">
<color rgba="0.34901960784313723618 0.37647058823529411242 0.4000000000000000222 1.0"/>
</material>
</visual>
<collision>
<origin xyz="-0.088875000000000023426 0.038874999999999992895 -0.0062500000000000159595" rpy="-1.5707963267948961139 -8.911581877347044605e-16 -2.9411789633500253405e-19" />
<geometry>
<mesh filename="meshes/d1-1_urdf.stl"/>
</geometry>
</collision>
<inertial>
<origin xyz="0.00081610826597224017664 0.0094232453162034490735 -0.0062500231253482460558" rpy="0 0 0"/>
<mass value="0.0096628566425330832124" />
<inertia ixx="8.3693839580018400824e-07" ixy="1.4748701787318260255e-08"  ixz="1.3783262349135136041e-13" iyy="3.146589634585134764e-07" iyz="2.231047263196122069e-12" izz="8.366669122257972871e-07" />
</inertial>
</link>

<joint name="pinky_34" type="revolute">
<origin xyz="0.026000000000000023093 -6.9388939039072283776e-18 -0.00050000000000000044409" rpy="-6.676764261657340823e-15 3.7042927579923252361e-14 -1.570796326794891673" />
<parent link="d2_1_urdf" />
<child link="d1_1_urdf" />
<axis xyz="0 0 1"/>
<limit effort="1000" velocity="20" lower="0" upper="1.570796326794896558"/>
<joint_properties friction="0.0"/>
</joint>

<joint name="pinky_23" type="revolute">
<origin xyz="-0.0010000000000000232227 -0.037874999999999992006 -0.00049999999999997962741" rpy="-1.2578385603382891612e-14 1.8225029649540626093e-14 -1.5707963267948943376" />
<parent link="d3_1_urdf" />
<child link="d2_1_urdf" />
<axis xyz="0 0 1"/>
<limit effort="1000" velocity="20" lower="0" upper="1.570796326794896558"/>
<joint_properties friction="0.0"/>
</joint>

<joint name="pinky_12" type="revolute">
<origin xyz="-0.015274999999999899769 0.0072500000000000168476 -0.0077499999999999669847" rpy="-1.5707963267949089925 -1.5707963267948836794 0" />
<parent link="d4_1_urdf" />
<child link="d3_1_urdf" />
<axis xyz="0 0 1"/>
<limit effort="1000" velocity="20" lower="-0.034906585039886590949" upper="1.570796326794896558"/>
<joint_properties friction="0.0"/>
</joint>

<joint name="pinky_01" type="revolute">
<origin xyz="-0.035563939448262263388 0.18909438839224834705 -0.014053824767915628138" rpy="-2.9670597283903603625 -1.6731615045569568627e-15 -1.4791665410651912982" />
<parent link="left_forearm_and_palm_assembly" />
<child link="d4_1_urdf" />
<axis xyz="0 0 1"/>
<limit effort="1000" velocity="20" lower="-0.29670597283903604735" upper="0.29670597283903604735"/>
<joint_properties friction="0.0"/>
</joint>

<link name="d4_2_urdf">
<visual>
<origin xyz="-0.079149999999999942624 1.7347234759768070944e-18 -0.0087499999999999990979" rpy="-3.141592653589793116 4.5554286607443344859e-19 -2.8599052452585355742e-18" />
<geometry>
<mesh filename="meshes/d4-2_urdf.stl"/>
</geometry>
<material name="d4-2_urdf_material">
<color rgba="0.34901960784313723618 0.37647058823529411242 0.4000000000000000222 1.0"/>
</material>
</visual>
<collision>
<origin xyz="-0.079149999999999942624 1.7347234759768070944e-18 -0.0087499999999999990979" rpy="-3.141592653589793116 4.5554286607443344859e-19 -2.8599052452585355742e-18" />
<geometry>
<mesh filename="meshes/d4-2_urdf.stl"/>
</geometry>
</collision>
<inertial>
<origin xyz="-0.0062842813664121255357 2.5879353915924891468e-10 -0.0081923602347070724472" rpy="0 0 0"/>
<mass value="0.007132231448786834245" />
<inertia ixx="4.8911025414963857278e-07" ixy="-2.0479711698014641934e-14"  ixz="1.4355227474224365445e-08" iyy="5.4026894403887864091e-07" iyz="1.5625068491834904642e-13" izz="7.1745332239577888655e-07" />
</inertial>
</link>

<link name="d3_2_urdf">
<visual>
<origin xyz="-0.063875000000000001221 0.0009999999999999731326 -0.00725000000000004894" rpy="-1.5707963267948976682 -5.6684318916166457318e-16 1.2835450087106675338e-18" />
<geometry>
<mesh filename="meshes/d3-2_urdf.stl"/>
</geometry>
<material name="d3-2_urdf_material">
<color rgba="0.34901960784313723618 0.37647058823529411242 0.4000000000000000222 1.0"/>
</material>
</visual>
<collision>
<origin xyz="-0.063875000000000001221 0.0009999999999999731326 -0.00725000000000004894" rpy="-1.5707963267948976682 -5.6684318916166457318e-16 1.2835450087106675338e-18" />
<geometry>
<mesh filename="meshes/d3-2_urdf.stl"/>
</geometry>
</collision>
<inertial>
<origin xyz="-0.00069598131543222041279 -0.013461728376310344926 -0.0072499999060333109036" rpy="0 0 0"/>
<mass value="0.022614819883081282992" />
<inertia ixx="4.0178611346719672687e-06" ixy="1.0347442960778410898e-07"  ixz="1.2277302836970954395e-14" iyy="1.34319724861492123e-06" iyz="-4.2659478056789841661e-14" izz="4.0893383736853734632e-06" />
</inertial>
</link>

<link name="d2_2_urdf">
<visual>
<origin xyz="-0.062875000000000014211 0.038875000000000006772 -0.0067500000000000927314" rpy="-1.570796326794896558 -1.6198741529116077739e-15 -2.3954916636228592295e-19" />
<geometry>
<mesh filename="meshes/d2-2_urdf.stl"/>
</geometry>
<material name="d2-2_urdf_material">
<color rgba="0.34901960784313723618 0.37647058823529411242 0.4000000000000000222 1.0"/>
</material>
</visual>
<collision>
<origin xyz="-0.062875000000000014211 0.038875000000000006772 -0.0067500000000000927314" rpy="-1.570796326794896558 -1.6198741529116077739e-15 -2.3954916636228592295e-19" />
<geometry>
<mesh filename="meshes/d2-2_urdf.stl"/>
</geometry>
</collision>
<inertial>
<origin xyz="0.0084939436722219624487 -0.00026229267814973505901 -0.0067499976398635620767" rpy="0 0 0"/>
<mass value="0.011864989574403404446" />
<inertia ixx="5.4043476975389825096e-07" ixy="-5.8686598046441902219e-08"  ixz="4.1185672886808004135e-14" iyy="1.221237368139783601e-06" iyz="1.4027739156421611987e-13" izz="1.1986582767035202684e-06" />
</inertial>
</link>

<link name="d1_2_urdf">
<visual>
<origin xyz="-0.088875000000000009548 0.038874999999999937383 -0.00625000000000001249" rpy="-1.5707963267948961139 -8.7074475476432480351e-16 -8.0935809896785430046e-20" />
<geometry>
<mesh filename="meshes/d1-2_urdf.stl"/>
</geometry>
<material name="d1-2_urdf_material">
<color rgba="0.34901960784313723618 0.37647058823529411242 0.4000000000000000222 1.0"/>
</material>
</visual>
<collision>
<origin xyz="-0.088875000000000009548 0.038874999999999937383 -0.00625000000000001249" rpy="-1.5707963267948961139 -8.7074475476432480351e-16 -8.0935809896785430046e-20" />
<geometry>
<mesh filename="meshes/d1-2_urdf.stl"/>
</geometry>
</collision>
<inertial>
<origin xyz="0.00081610826597225405443 0.0094232453162033935623 -0.0062500231253482434537" rpy="0 0 0"/>
<mass value="0.0096628566425330797429" />
<inertia ixx="8.3693839580018422e-07" ixy="1.4748701787318250329e-08"  ixz="1.3783262347010174479e-13" iyy="3.1465896345851337052e-07" iyz="2.2310472631933400279e-12" izz="8.366669122257972871e-07" />
</inertial>
</link>

<joint name="ring_34" type="revolute">
<origin xyz="0.026000000000000023093 -5.5480658045156672209e-18 -0.0004999999999999935052" rpy="-6.1718292015265208845e-15 -1.880291476011778168e-15 -1.5707963267949636155" />
<parent link="d2_2_urdf" />
<child link="d1_2_urdf" />
<axis xyz="0 0 1"/>
<limit effort="1000" velocity="20" lower="0" upper="1.570796326794896558"/>
<joint_properties friction="0.0"/>
</joint>

<joint name="ring_23" type="revolute">
<origin xyz="-0.0010000000000000060923 -0.037875000000000047518 -0.00049999999999998136213" rpy="-5.4793072159929147617e-15 -5.3720603953769649706e-15 -1.5707963267948943376" />
<parent link="d3_2_urdf" />
<child link="d2_2_urdf" />
<axis xyz="0 0 1"/>
<limit effort="1000" velocity="20" lower="0" upper="1.570796326794896558"/>
<joint_properties friction="0.0"/>
</joint>

<joint name="ring_12" type="revolute">
<origin xyz="-0.015274999999999983036 0.0072500000000000029698 -0.0077499999999999956077" rpy="-1.5707963267949021091 -1.5707963267948907848 0" />
<parent link="d4_2_urdf" />
<child link="d3_2_urdf" />
<axis xyz="0 0 1"/>
<limit effort="1000" velocity="20" lower="-0.034906585039886590949" upper="1.570796326794896558"/>
<joint_properties friction="0.0"/>
</joint>

<joint name="ring_01" type="revolute">
<origin xyz="-0.012184348636380765152 0.19516197601440885001 -0.010513965579231784181" rpy="-3.0545918230670441318 -0.0068123514634775231974 -1.5321205940965849646" />
<parent link="left_forearm_and_palm_assembly" />
<child link="d4_2_urdf" />
<axis xyz="0 0 1"/>
<limit effort="1000" velocity="20" lower="-0.29670597283903604735" upper="0.29670597283903604735"/>
<joint_properties friction="0.0"/>
</joint>

<link name="d4_3_urdf">
<visual>
<origin xyz="-0.079149999999999998135 0 -0.0087500000000000008327" rpy="3.141592653589793116 -0 -2.7571401197661538688e-30" />
<geometry>
<mesh filename="meshes/d4-3_urdf.stl"/>
</geometry>
<material name="d4-3_urdf_material">
<color rgba="0.34901960784313723618 0.37647058823529411242 0.4000000000000000222 1.0"/>
</material>
</visual>
<collision>
<origin xyz="-0.079149999999999998135 0 -0.0087500000000000008327" rpy="3.141592653589793116 -0 -2.7571401197661538688e-30" />
<geometry>
<mesh filename="meshes/d4-3_urdf.stl"/>
</geometry>
</collision>
<inertial>
<origin xyz="-0.0062842813664121671691 2.5879353744798092046e-10 -0.0081923602347070741819" rpy="0 0 0"/>
<mass value="0.0071322314487868359797" />
<inertia ixx="4.8911025414963867866e-07" ixy="-2.0479711690979226971e-14"  ixz="1.4355227474224373716e-08" iyy="5.4026894403887874679e-07" iyz="1.5625068491580762688e-13" izz="7.1745332239577878067e-07" />
</inertial>
</link>

<link name="d3_3_urdf">
<visual>
<origin xyz="-0.063875000000000028977 0.0010000000000000008882 -0.0072500000000000498074" rpy="-1.5707963267948976682 -5.8880953492685305182e-16 -5.9492368458015668761e-32" />
<geometry>
<mesh filename="meshes/d3-3_urdf.stl"/>
</geometry>
<material name="d3-3_urdf_material">
<color rgba="0.34901960784313723618 0.37647058823529411242 0.4000000000000000222 1.0"/>
</material>
</visual>
<collision>
<origin xyz="-0.063875000000000028977 0.0010000000000000008882 -0.0072500000000000498074" rpy="-1.5707963267948976682 -5.8880953492685305182e-16 -5.9492368458015668761e-32" />
<geometry>
<mesh filename="meshes/d3-3_urdf.stl"/>
</geometry>
</collision>
<inertial>
<origin xyz="-0.00069598131543222030437 -0.01346172837631032064 -0.0072499999060333091688" rpy="0 0 0"/>
<mass value="0.022614819883081289931" />
<inertia ixx="4.0178611346720790771e-06" ixy="1.0347442960778401634e-07"  ixz="1.2277342610578212517e-14" iyy="1.3431972486150069921e-06" iyz="-4.2659478106741681693e-14" izz="4.0893383736853514403e-06" />
</inertial>
</link>

<link name="d2_3_urdf">
<visual>
<origin xyz="-0.062874999999999986455 0.038875000000000006772 -0.0067500000000000953335" rpy="-1.57079632679489678 -1.6156388965885167424e-15 0" />
<geometry>
<mesh filename="meshes/d2-3_urdf.stl"/>
</geometry>
<material name="d2-3_urdf_material">
<color rgba="0.34901960784313723618 0.37647058823529411242 0.4000000000000000222 1.0"/>
</material>
</visual>
<collision>
<origin xyz="-0.062874999999999986455 0.038875000000000006772 -0.0067500000000000953335" rpy="-1.57079632679489678 -1.6156388965885167424e-15 0" />
<geometry>
<mesh filename="meshes/d2-3_urdf.stl"/>
</geometry>
</collision>
<inertial>
<origin xyz="0.0084939436722219902043 -0.00026229267814973505901 -0.0067499976398635638114" rpy="0 0 0"/>
<mass value="0.011864989574403404446" />
<inertia ixx="5.4043476975389814508e-07" ixy="-5.8686598046441862515e-08"  ixz="4.1185672854261180908e-14" iyy="1.2212373681397833892e-06" iyz="1.4027739154023800477e-13" izz="1.1986582767035206919e-06" />
</inertial>
</link>

<link name="d1_3_urdf">
<visual>
<origin xyz="-0.088875000000000009548 0.038875000000000048406 -0.00625000000000001249" rpy="-1.5707963267948961139 -8.7170368868848045656e-16 8.1721059400302039953e-30" />
<geometry>
<mesh filename="meshes/d1-3_urdf.stl"/>
</geometry>
<material name="d1-3_urdf_material">
<color rgba="0.34901960784313723618 0.37647058823529411242 0.4000000000000000222 1.0"/>
</material>
</visual>
<collision>
<origin xyz="-0.088875000000000009548 0.038875000000000048406 -0.00625000000000001249" rpy="-1.5707963267948961139 -8.7170368868848045656e-16 8.1721059400302039953e-30" />
<geometry>
<mesh filename="meshes/d1-3_urdf.stl"/>
</geometry>
</collision>
<inertial>
<origin xyz="0.00081610826597226793222 0.0094232453162035045846 -0.0062500231253482443211" rpy="0 0 0"/>
<mass value="0.0096628566425330814776" />
<inertia ixx="8.3693839580018422e-07" ixy="1.4748701787318253638e-08"  ixz="1.3783262349187137752e-13" iyy="3.1465896345851337052e-07" iyz="2.2310472631914635235e-12" izz="8.366669122257972871e-07" />
</inertial>
</link>

<joint name="middle_34" type="revolute">
<origin xyz="0.026000000000000023093 1.1926223897340548774e-18 -0.00049999999999999610728" rpy="1.3265464408158250387e-15 -6.1080605183085887417e-16 -1.5707963267948539254" />
<parent link="d2_3_urdf" />
<child link="d1_3_urdf" />
<axis xyz="0 0 1"/>
<limit effort="1000" velocity="20" lower="0" upper="1.570796326794896558"/>
<joint_properties friction="0.0"/>
</joint>

<joint name="middle_23" type="revolute">
<origin xyz="-0.0010000000000000221385 -0.037874999999999992006 -0.00049999999999997789268" rpy="-5.4515351981154857533e-15 4.3891486552074824319e-15 -1.5707963267948930053" />
<parent link="d3_3_urdf" />
<child link="d2_3_urdf" />
<axis xyz="0 0 1"/>
<limit effort="1000" velocity="20" lower="0" upper="1.570796326794896558"/>
<joint_properties friction="0.0"/>
</joint>

<joint name="middle_12" type="revolute">
<origin xyz="-0.015274999999999983036 0.0072500000000000090414 -0.0077499999999999808625" rpy="-1.5707963267949005548 -1.5707963267948910069 0" />
<parent link="d4_3_urdf" />
<child link="d3_3_urdf" />
<axis xyz="0 0 1"/>
<limit effort="1000" velocity="20" lower="-0.034906585039886590949" upper="1.570796326794896558"/>
<joint_properties friction="0.0"/>
</joint>

<joint name="middle_01" type="revolute">
<origin xyz="0.011338454601756808859 0.19914999999999999369 -0.008000647022553254023" rpy="3.141592653589793116 -1.2172988537662788118e-17 -1.5707963267948521491" />
<parent link="left_forearm_and_palm_assembly" />
<child link="d4_3_urdf" />
<axis xyz="0 0 1"/>
<limit effort="1000" velocity="20" lower="-0.29670597283903604735" upper="0.29670597283903604735"/>
<joint_properties friction="0.0"/>
</joint>

<link name="d4_4_urdf">
<visual>
<origin xyz="-0.079149999999999970379 3.4694469519536141888e-18 -0.0087500000000000008327" rpy="-3.141592653589793116 -4.0755832188195871094e-20 2.4494957862026035141e-18" />
<geometry>
<mesh filename="meshes/d4-4_urdf.stl"/>
</geometry>
<material name="d4-4_urdf_material">
<color rgba="0.34901960784313723618 0.37647058823529411242 0.4000000000000000222 1.0"/>
</material>
</visual>
<collision>
<origin xyz="-0.079149999999999970379 3.4694469519536141888e-18 -0.0087500000000000008327" rpy="-3.141592653589793116 -4.0755832188195871094e-20 2.4494957862026035141e-18" />
<geometry>
<mesh filename="meshes/d4-4_urdf.stl"/>
</geometry>
</collision>
<inertial>
<origin xyz="-0.0062842813664121532913 2.5879354137279462533e-10 -0.0081923602347070741819" rpy="0 0 0"/>
<mass value="0.0071322314487868359797" />
<inertia ixx="4.8911025414963857278e-07" ixy="-2.0479711695842311483e-14"  ixz="1.4355227474224372062e-08" iyy="5.4026894403887885267e-07" iyz="1.5625068490914370861e-13" izz="7.1745332239577888655e-07" />
</inertial>
</link>

<link name="d3_4_urdf">
<visual>
<origin xyz="-0.063875000000000015099 0.0010000000000000008882 -0.0072500000000000446032" rpy="-1.5707963267948976682 -5.8894923608858858138e-16 1.0622700542522094662e-19" />
<geometry>
<mesh filename="meshes/d3-4_urdf.stl"/>
</geometry>
<material name="d3-4_urdf_material">
<color rgba="0.34901960784313723618 0.37647058823529411242 0.4000000000000000222 1.0"/>
</material>
</visual>
<collision>
<origin xyz="-0.063875000000000015099 0.0010000000000000008882 -0.0072500000000000446032" rpy="-1.5707963267948976682 -5.8894923608858858138e-16 1.0622700542522094662e-19" />
<geometry>
<mesh filename="meshes/d3-4_urdf.stl"/>
</geometry>
</collision>
<inertial>
<origin xyz="-0.00069598131543220631817 -0.013461728376310315436 -0.0072499999060333039647" rpy="0 0 0"/>
<mass value="0.022614819883081289931" />
<inertia ixx="4.0178611346720799241e-06" ixy="1.0347442960778391046e-07"  ixz="1.2277342634794511546e-14" iyy="1.3431972486150069921e-06" iyz="-4.2659478019031191137e-14" izz="4.0893383736853531344e-06" />
</inertial>
</link>

<link name="d2_4_urdf">
<visual>
<origin xyz="-0.062875000000000014211 0.03887500000000002065 -0.0067500000000000892619" rpy="-1.57079632679489678 -1.6160650026726845723e-15 -1.0322563581737492367e-19" />
<geometry>
<mesh filename="meshes/d2-4_urdf.stl"/>
</geometry>
<material name="d2-4_urdf_material">
<color rgba="0.34901960784313723618 0.37647058823529411242 0.4000000000000000222 1.0"/>
</material>
</visual>
<collision>
<origin xyz="-0.062875000000000014211 0.03887500000000002065 -0.0067500000000000892619" rpy="-1.57079632679489678 -1.6160650026726845723e-15 -1.0322563581737492367e-19" />
<geometry>
<mesh filename="meshes/d2-4_urdf.stl"/>
</geometry>
</collision>
<inertial>
<origin xyz="0.0084939436722219624487 -0.00026229267814972812012 -0.0067499976398635568725" rpy="0 0 0"/>
<mass value="0.011864989574403404446" />
<inertia ixx="5.4043476975389825096e-07" ixy="-5.8686598046441869132e-08"  ixz="4.1185672855867472105e-14" iyy="1.2212373681397840245e-06" iyz="1.402773915149899372e-13" izz="1.1986582767035211154e-06" />
</inertial>
</link>

<link name="d1_4_urdf">
<visual>
<origin xyz="-0.088875000000000023426 0.038874999999999992895 -0.0062500000000000090206" rpy="-1.5707963267948961139 -8.835632025403370409e-16 3.2013798096619042787e-19" />
<geometry>
<mesh filename="meshes/d1-4_urdf.stl"/>
</geometry>
<material name="d1-4_urdf_material">
<color rgba="0.34901960784313723618 0.37647058823529411242 0.4000000000000000222 1.0"/>
</material>
</visual>
<collision>
<origin xyz="-0.088875000000000023426 0.038874999999999992895 -0.0062500000000000090206" rpy="-1.5707963267948961139 -8.835632025403370409e-16 3.2013798096619042787e-19" />
<geometry>
<mesh filename="meshes/d1-4_urdf.stl"/>
</geometry>
</collision>
<inertial>
<origin xyz="0.00081610826597225405443 0.0094232453162034525429 -0.0062500231253482399843" rpy="0 0 0"/>
<mass value="0.0096628566425330814776" />
<inertia ixx="8.3693839580018422e-07" ixy="1.4748701787318261909e-08"  ixz="1.3783262349255403881e-13" iyy="3.1465896345851337052e-07" iyz="2.2310472631784725873e-12" izz="8.366669122257972871e-07" />
</inertial>
</link>

<joint name="index_34" type="revolute">
<origin xyz="0.026000000000000050848 -4.4452289071905681794e-18 -0.00050000000000000391354" rpy="1.2357909421332665112e-14 -7.9221968534233800336e-15 -1.5707963267948981123" />
<parent link="d2_4_urdf" />
<child link="d1_4_urdf" />
<axis xyz="0 0 1"/>
<limit effort="1000" velocity="20" lower="0" upper="1.570796326794896558"/>
<joint_properties friction="0.0"/>
</joint>

<joint name="index_23" type="revolute">
<origin xyz="-0.0010000000000000145491 -0.037874999999999992006 -0.0004999999999999865663" rpy="-1.5675694232603572063e-14 2.0630279039050681443e-14 -1.5707963267948918951" />
<parent link="d3_4_urdf" />
<child link="d2_4_urdf" />
<axis xyz="0 0 1"/>
<limit effort="1000" velocity="20" lower="0" upper="1.570796326794896558"/>
<joint_properties friction="0.0"/>
</joint>

<joint name="index_12" type="revolute">
<origin xyz="-0.015275000000000010791 0.0072500000000000099087 -0.007749999999999984332" rpy="-1.5707963267949147657 -1.5707963267948774622 0" />
<parent link="d4_4_urdf" />
<child link="d3_4_urdf" />
<axis xyz="0 0 1"/>
<limit effort="1000" velocity="20" lower="-0.034906585039886590949" upper="1.570796326794896558"/>
<joint_properties friction="0.0"/>
</joint>

<joint name="index_01" type="revolute">
<origin xyz="0.034861257839894611854 0.19513802398559085272 -0.010513965579232117248" rpy="3.0543261909900736306 -2.5433214562164911737e-15 -1.6100662349647953953" />
<parent link="left_forearm_and_palm_assembly" />
<child link="d4_4_urdf" />
<axis xyz="0 0 1"/>
<limit effort="1000" velocity="20" lower="-0.29670597283903604735" upper="0.29670597283903604735"/>
<joint_properties friction="0.0"/>
</joint>


</robot>
