<!-- 

Sarcomere Dynamics Software License Notice
- - - - - - - - - - - - - - - - - - - - - -
This software is developed by Sarcomere Dynamics Inc. for use with the ARTUS family of robotic products,
including ARTUS Lite, ARTUS+, ARTUS Dex, and Hyperion.

Copyright (c) 2023–2025, Sarcomere Dynamics Inc. All rights reserved.

Licensed under the Sarcomere Dynamics Software License.
See the LICENSE file in the repository for full details.
-->

<robot name="ArtusLite_RightHand">
<link name="right_forearm_and_palm_assembly">
<visual>
<origin xyz="-2.5931183038634623242e-18 0.10624999999999998335 -0.00092800153782065695433" rpy="-1.570796326794896558 -0 0" />
<geometry>
<mesh filename="meshes/base_plate.stl"/>
</geometry>
<material name="base_plate_material">
<color rgba="0.91764705882352937127 0.91764705882352937127 0.91764705882352937127 1.0"/>
</material>
</visual>
<collision>
<origin xyz="-2.5931183038634623242e-18 0.10624999999999998335 -0.00092800153782065695433" rpy="-1.570796326794896558 -0 0" />
<geometry>
<mesh filename="meshes/base_plate.stl"/>
</geometry>
</collision>
<visual>
<origin xyz="-1.2143064331837649661e-17 0.10624999999999999722 -0.00092800153782066682057" rpy="-1.570796326794896558 -0 0" />
<geometry>
<mesh filename="meshes/forearm_urdf_2.stl"/>
</geometry>
<material name="forearm_urdf_2_material">
<color rgba="0.91764705882352937127 0.91764705882352937127 0.91764705882352937127 1.0"/>
</material>
</visual>
<collision>
<origin xyz="-1.2143064331837649661e-17 0.10624999999999999722 -0.00092800153782066682057" rpy="-1.570796326794896558 -0 0" />
<geometry>
<mesh filename="meshes/forearm_urdf_2.stl"/>
</geometry>
</collision>
<visual>
<origin xyz="0.020567624083538432744 0.14039834978141410571 -0.024700000000000048306" rpy="-3.141592653589793116 3.9820835674533535966e-28 2.775555973380359814e-16" />
<geometry>
<mesh filename="meshes/right_palm_urdf.stl"/>
</geometry>
<material name="right_palm_urdf_material">
<color rgba="0.34901960784313723618 0.37647058823529411242 0.4000000000000000222 1.0"/>
</material>
</visual>
<collision>
<origin xyz="0.020567624083538432744 0.14039834978141410571 -0.024700000000000048306" rpy="-3.141592653589793116 3.9820835674533535966e-28 2.775555973380359814e-16" />
<geometry>
<mesh filename="meshes/right_palm_urdf.stl"/>
</geometry>
</collision>
<inertial>
<origin xyz="0.00030369490604576675685 0.091404042575096766665 0.0013153559624050467549" rpy="0 0 0"/>
<mass value="0.61832415660282591396" />
<inertia ixx="0.0026873060385701813199" ixy="-2.2840126824090747692e-05"  ixz="6.4840618162704540973e-06" iyy="0.00062249804936853701115" iyz="-8.7529080793696096251e-05" izz="0.002723777543353417957" />
</inertial>
</link>

<link name="t4_urdf">
<visual>
<origin xyz="-0.083899999999999974598 2.4286128663675299322e-17 -0.0097500000000000086597" rpy="3.141592653589793116 -1.2794653093373542632e-18 -3.2844435264478311648e-17" />
<geometry>
<mesh filename="meshes/t4_urdf.stl"/>
</geometry>
<material name="t4_urdf_material">
<color rgba="0.34901960784313723618 0.37647058823529411242 0.4000000000000000222 1.0"/>
</material>
</visual>
<collision>
<origin xyz="-0.083899999999999974598 2.4286128663675299322e-17 -0.0097500000000000086597" rpy="3.141592653589793116 -1.2794653093373542632e-18 -3.2844435264478311648e-17" />
<geometry>
<mesh filename="meshes/t4_urdf.stl"/>
</geometry>
</collision>
<inertial>
<origin xyz="-0.0058427530488760759386 -3.1276186291250648012e-10 -0.010494198053015374797" rpy="0 0 0"/>
<mass value="0.010288104754589431911" />
<inertia ixx="9.0136774732367771637e-07" ixy="-8.7726063652447926106e-14"  ixz="1.6540276525723786771e-08" iyy="9.0496845343764967793e-07" iyz="-2.4535322478556142675e-12" izz="1.162568781635075908e-06" />
</inertial>
</link>

<link name="t3_urdf">
<visual>
<origin xyz="-0.067375000000000045963 -7.5000000000033373304e-05 -0.0087500000000000632827" rpy="-1.5707963267948976682 -6.2308664708005556299e-16 6.9434614612816685322e-17" />
<geometry>
<mesh filename="meshes/t3_urdf.stl"/>
</geometry>
<material name="t3_urdf_material">
<color rgba="0.34901960784313723618 0.37647058823529411242 0.4000000000000000222 1.0"/>
</material>
</visual>
<collision>
<origin xyz="-0.067375000000000045963 -7.5000000000033373304e-05 -0.0087500000000000632827" rpy="-1.5707963267948976682 -6.2308664708005556299e-16 6.9434614612816685322e-17" />
<geometry>
<mesh filename="meshes/t3_urdf.stl"/>
</geometry>
</collision>
<inertial>
<origin xyz="-0.00088723630070691728022 -0.0145454672523326594 -0.0087499987535804481936" rpy="0 0 0"/>
<mass value="0.030585609045160676994" />
<inertia ixx="6.3609316339689915345e-06" ixy="1.7049934843751177605e-07"  ixz="-5.4125620478942359379e-13" iyy="2.239427031737983397e-06" iyz="4.5912259882826398067e-13" izz="6.4143771252919357041e-06" />
</inertial>
</link>

<link name="t2_urdf">
<visual>
<origin xyz="-0.067450000000000037703 0.040300000000000016365 -0.0072500000000001001144" rpy="-1.570796326794896558 -1.5517967110789131212e-15 -6.3719847758218301958e-17" />
<geometry>
<mesh filename="meshes/t2_urdf.stl"/>
</geometry>
<material name="t2_urdf_material">
<color rgba="0.34901960784313723618 0.37647058823529411242 0.4000000000000000222 1.0"/>
</material>
</visual>
<collision>
<origin xyz="-0.067450000000000037703 0.040300000000000016365 -0.0072500000000001001144" rpy="-1.570796326794896558 -1.5517967110789131212e-15 -6.3719847758218301958e-17" />
<geometry>
<mesh filename="meshes/t2_urdf.stl"/>
</geometry>
</collision>
<inertial>
<origin xyz="0.0091415418957211530548 -0.0010488393377385205052 -0.0072499940743800013465" rpy="0 0 0"/>
<mass value="0.014650153995995354728" />
<inertia ixx="7.8231186604362120536e-07" ixy="-1.0095612977356371713e-07"  ixz="-1.4446714791995146714e-13" iyy="1.7012075450947944876e-06" iyz="1.9146541620404207488e-13" izz="1.7152649221519815688e-06" />
</inertial>
</link>

<link name="t1_urdf">
<visual>
<origin xyz="-0.094450000000000047806 0.040300000000000030242 -0.0062500000000000211636" rpy="-1.5707963267948961139 -9.7518361293170801771e-16 -3.0377457227063286795e-18" />
<geometry>
<mesh filename="meshes/t1_urdf.stl"/>
</geometry>
<material name="t1_urdf_material">
<color rgba="0.34901960784313723618 0.37647058823529411242 0.4000000000000000222 1.0"/>
</material>
</visual>
<collision>
<origin xyz="-0.094450000000000047806 0.040300000000000030242 -0.0062500000000000211636" rpy="-1.5707963267948961139 -9.7518361293170801771e-16 -3.0377457227063286795e-18" />
<geometry>
<mesh filename="meshes/t1_urdf.stl"/>
</geometry>
</collision>
<inertial>
<origin xyz="0.0010824005610924614107 0.010114885903667120842 -0.0062499582332070412541" rpy="0 0 0"/>
<mass value="0.011648615104359208092" />
<inertia ixx="1.0781644849112865646e-06" ixy="2.8463521071749734493e-08"  ixz="-2.6682779571079549703e-12" iyy="4.5092952838927348289e-07" iyz="-5.6995504512631655219e-12" izz="1.1054367169332249318e-06" />
</inertial>
</link>

<joint name="thumb_34" type="revolute">
<origin xyz="0.026999999999999996225 2.7755575615628913511e-17 -0.0010000000000000251743" rpy="2.0108136658001474543e-14 -1.3535182064577502269e-14 -1.57079632679489678" />
<parent link="t2_urdf" />
<child link="t1_urdf" />
<axis xyz="0 0 1"/>
<limit effort="1000" velocity="20" lower="0" upper="1.570796326794896558"/>
<joint_properties friction="0.0"/>
</joint>

<joint name="thumb_23" type="revolute">
<origin xyz="7.4999999999991739941e-05 -0.040375000000000021982 -0.0014999999999999820335" rpy="1.5022520038205650076e-14 2.0353434029585057533e-14 -1.5707963267948945596" />
<parent link="t3_urdf" />
<child link="t2_urdf" />
<axis xyz="0 0 1"/>
<limit effort="1000" velocity="20" lower="0" upper="1.570796326794896558"/>
<joint_properties friction="0.0"/>
</joint>

<joint name="thumb_12" type="revolute">
<origin xyz="-0.016524999999999963329 0.0087500000000000320577 -0.0098250000000000003997" rpy="-1.570796326794901443 -1.2740903539558616764 -4.5001425164792760456e-15" />
<parent link="t4_urdf" />
<child link="t3_urdf" />
<axis xyz="0 0 1"/>
<limit effort="1000" velocity="20" lower="0.29670597283903604735" upper="1.570796326794896558"/>
<joint_properties friction="0.0"/>
</joint>

<joint name="thumb_01" type="revolute">
<origin xyz="0.015093519578924775859 0.14573355735843276926 0.026000647022553280419" rpy="1.5707963267948972241 0.79305228016606710284 -2.9670597283903594743" />
<parent link="right_forearm_and_palm_assembly" />
<child link="t4_urdf" />
<axis xyz="0 0 1"/>
<limit effort="1000" velocity="20" lower="-0.785398163397448279" upper="0.785398163397448279"/>
<joint_properties friction="0.0"/>
</joint>

<link name="d4-1_urdf">
<visual>
<origin xyz="-0.07915000000000002589 3.4694469519536141888e-18 -0.0087499999999999990979" rpy="-3.141592653589793116 -7.4443567559721403992e-19 1.0353695998231723084e-17" />
<geometry>
<mesh filename="meshes/d4-1_urdf.stl"/>
</geometry>
<material name="d4-1_urdf_material">
<color rgba="0.34901960784313723618 0.37647058823529411242 0.4000000000000000222 1.0"/>
</material>
</visual>
<collision>
<origin xyz="-0.07915000000000002589 3.4694469519536141888e-18 -0.0087499999999999990979" rpy="-3.141592653589793116 -7.4443567559721403992e-19 1.0353695998231723084e-17" />
<geometry>
<mesh filename="meshes/d4-1_urdf.stl"/>
</geometry>
</collision>
<inertial>
<origin xyz="-0.0062842813664121949246 2.587935421054313373e-10 -0.0081923602347070724472" rpy="0 0 0"/>
<mass value="0.007132231448786834245" />
<inertia ixx="4.8911025414963878454e-07" ixy="-2.0479711673097400547e-14"  ixz="1.4355227474224367099e-08" iyy="5.4026894403887874679e-07" iyz="1.5625068491430874067e-13" izz="7.1745332239577899243e-07" />
</inertial>
</link>

<link name="d3-1_urdf">
<visual>
<origin xyz="-0.063875000000000001221 0.0010000000000000286438 -0.0072500000000000515421" rpy="-1.5707963267948976682 -5.8030354937565350676e-16 2.0073644290647640091e-18" />
<geometry>
<mesh filename="meshes/d3-1_urdf.stl"/>
</geometry>
<material name="d3-1_urdf_material">
<color rgba="0.34901960784313723618 0.37647058823529411242 0.4000000000000000222 1.0"/>
</material>
</visual>
<collision>
<origin xyz="-0.063875000000000001221 0.0010000000000000286438 -0.0072500000000000515421" rpy="-1.5707963267948976682 -5.8030354937565350676e-16 2.0073644290647640091e-18" />
<geometry>
<mesh filename="meshes/d3-1_urdf.stl"/>
</geometry>
</collision>
<inertial>
<origin xyz="-0.00069598131543220631817 -0.013461728376310289415 -0.0072499999060333126383" rpy="0 0 0"/>
<mass value="0.022614819883081289931" />
<inertia ixx="4.0178611346719698098e-06" ixy="1.0347442960778391046e-07"  ixz="1.2277302955994313018e-14" iyy="1.3431972486149210183e-06" iyz="-4.2659478151407238582e-14" izz="4.0893383736853743102e-06" />
</inertial>
</link>

<link name="d2-1_urdf">
<visual>
<origin xyz="-0.0628749999999999587 0.038875000000000006772 -0.0067500000000000962008" rpy="-1.57079632679489678 -1.5927435854182864622e-15 -3.5942939148162164478e-18" />
<geometry>
<mesh filename="meshes/d2-1_urdf.stl"/>
</geometry>
<material name="d2-1_urdf_material">
<color rgba="0.34901960784313723618 0.37647058823529411242 0.4000000000000000222 1.0"/>
</material>
</visual>
<collision>
<origin xyz="-0.0628749999999999587 0.038875000000000006772 -0.0067500000000000962008" rpy="-1.57079632679489678 -1.5927435854182864622e-15 -3.5942939148162164478e-18" />
<geometry>
<mesh filename="meshes/d2-1_urdf.stl"/>
</geometry>
</collision>
<inertial>
<origin xyz="0.0084939436722220040821 -0.00026229267814973505901 -0.0067499976398635664135" rpy="0 0 0"/>
<mass value="0.011864989574403404446" />
<inertia ixx="5.404347697538980392e-07" ixy="-5.8686598046441855897e-08"  ixz="4.1185672876752331067e-14" iyy="1.2212373681397833892e-06" iyz="1.402773914831797586e-13" izz="1.1986582767035206919e-06" />
</inertial>
</link>

<link name="d1-1_urdf">
<visual>
<origin xyz="-0.088875000000000009548 0.038874999999999937383 -0.00625000000000001249" rpy="-1.5707963267948961139 -8.5497560105453835645e-16 -2.3624031506968628575e-18" />
<geometry>
<mesh filename="meshes/d1-1_urdf.stl"/>
</geometry>
<material name="d1-1_urdf_material">
<color rgba="0.34901960784313723618 0.37647058823529411242 0.4000000000000000222 1.0"/>
</material>
</visual>
<collision>
<origin xyz="-0.088875000000000009548 0.038874999999999937383 -0.00625000000000001249" rpy="-1.5707963267948961139 -8.5497560105453835645e-16 -2.3624031506968628575e-18" />
<geometry>
<mesh filename="meshes/d1-1_urdf.stl"/>
</geometry>
</collision>
<inertial>
<origin xyz="0.00081610826597225405443 0.0094232453162033935623 -0.0062500231253482460558" rpy="0 0 0"/>
<mass value="0.0096628566425330832124" />
<inertia ixx="8.3693839580018400824e-07" ixy="1.4748701787318258601e-08"  ixz="1.3783262347665527302e-13" iyy="3.146589634585134764e-07" iyz="2.2310472631920831011e-12" izz="8.366669122257972871e-07" />
</inertial>
</link>

<joint name="pinky_34" type="revolute">
<origin xyz="0.026000000000000023093 -8.2399365108898336985e-18 -0.00050000000000000044409" rpy="5.0133770924262931337e-15 1.4789047887596532477e-15 -1.5707963267948970021" />
<parent link="d2-1_urdf" />
<child link="d1-1_urdf" />
<axis xyz="0 0 1"/>
<limit effort="1000" velocity="20" lower="0" upper="1.570796326794896558"/>
<joint_properties friction="0.0"/>
</joint>

<joint name="pinky_23" type="revolute">
<origin xyz="-0.00099999999999997790309 -0.037874999999999992006 -0.00049999999999997789268" rpy="-2.7917766663472194013e-15 -4.5153227605194488046e-15 -1.5707963267948992225" />
<parent link="d3-1_urdf" />
<child link="d2-1_urdf" />
<axis xyz="0 0 1"/>
<limit effort="1000" velocity="20" lower="0" upper="1.570796326794896558"/>
<joint_properties friction="0.0"/>
</joint>

<joint name="pinky_12" type="revolute">
<origin xyz="-0.015274999999999983036 0.0072500000000000151129 -0.0077499999999999895361" rpy="-1.5707963267948918951 -1.5707963267948952257 0" />
<parent link="d4-1_urdf" />
<child link="d3-1_urdf" />
<axis xyz="0 0 1"/>
<limit effort="1000" velocity="20" lower="-0.034906585039886590949" upper="1.570796326794896558"/>
<joint_properties friction="0.0"/>
</joint>

<joint name="pinky_01" type="revolute">
<origin xyz="-0.034763939448262448639 0.18909438839224834705 0.014053824767915723548" rpy="-0.17453292519943353067 1.1456913421203554045e-15 -1.4791665410651946289" />
<parent link="right_forearm_and_palm_assembly" />
<child link="d4-1_urdf" />
<axis xyz="0 0 1"/>
<limit effort="1000" velocity="20" lower="-0.29670597283903604735" upper="0.29670597283903604735"/>
<joint_properties friction="0.0"/>
</joint>

<link name="d4-2_urdf">
<visual>
<origin xyz="-0.079149999999999970379 -8.6736173798840354721e-19 -0.0087500000000000025674" rpy="-3.141592653589793116 -4.4379798391390675312e-19 -5.6380848503814306952e-20" />
<geometry>
<mesh filename="meshes/d4-2_urdf.stl"/>
</geometry>
<material name="d4-2_urdf_material">
<color rgba="0.34901960784313723618 0.37647058823529411242 0.4000000000000000222 1.0"/>
</material>
</visual>
<collision>
<origin xyz="-0.079149999999999970379 -8.6736173798840354721e-19 -0.0087500000000000025674" rpy="-3.141592653589793116 -4.4379798391390675312e-19 -5.6380848503814306952e-20" />
<geometry>
<mesh filename="meshes/d4-2_urdf.stl"/>
</geometry>
</collision>
<inertial>
<origin xyz="-0.0062842813664121394135 2.5879353675157404723e-10 -0.0081923602347070759166" rpy="0 0 0"/>
<mass value="0.007132231448786834245" />
<inertia ixx="4.8911025414963878454e-07" ixy="-2.0479711696808625071e-14"  ixz="1.4355227474224368753e-08" iyy="5.4026894403887885267e-07" iyz="1.5625068490221576805e-13" izz="7.1745332239577888655e-07" />
</inertial>
</link>

<link name="d3-2_urdf">
<visual>
<origin xyz="-0.063875000000000015099 0.0009999999999999731326 -0.0072500000000000480727" rpy="-1.5707963267948976682 -5.7868441810112084639e-16 -4.128432274470162884e-19" />
<geometry>
<mesh filename="meshes/d3-2_urdf.stl"/>
</geometry>
<material name="d3-2_urdf_material">
<color rgba="0.34901960784313723618 0.37647058823529411242 0.4000000000000000222 1.0"/>
</material>
</visual>
<collision>
<origin xyz="-0.063875000000000015099 0.0009999999999999731326 -0.0072500000000000480727" rpy="-1.5707963267948976682 -5.7868441810112084639e-16 -4.128432274470162884e-19" />
<geometry>
<mesh filename="meshes/d3-2_urdf.stl"/>
</geometry>
</collision>
<inertial>
<origin xyz="-0.00069598131543222041279 -0.013461728376310341457 -0.0072499999060333091688" rpy="0 0 0"/>
<mass value="0.022614819883081282992" />
<inertia ixx="4.0178611346719689628e-06" ixy="1.0347442960778410898e-07"  ixz="1.2277302900818601361e-14" iyy="1.3431972486149208065e-06" iyz="-4.2659478085240154384e-14" izz="4.0893383736853734632e-06" />
</inertial>
</link>

<link name="d2-2_urdf">
<visual>
<origin xyz="-0.062874999999999986455 0.038875000000000013711 -0.0067500000000000944661" rpy="-1.570796326794896558 -1.616246095983500399e-15 -1.1239805910186888482e-18" />
<geometry>
<mesh filename="meshes/d2-2_urdf.stl"/>
</geometry>
<material name="d2-2_urdf_material">
<color rgba="0.34901960784313723618 0.37647058823529411242 0.4000000000000000222 1.0"/>
</material>
</visual>
<collision>
<origin xyz="-0.062874999999999986455 0.038875000000000013711 -0.0067500000000000944661" rpy="-1.570796326794896558 -1.616246095983500399e-15 -1.1239805910186888482e-18" />
<geometry>
<mesh filename="meshes/d2-2_urdf.stl"/>
</geometry>
</collision>
<inertial>
<origin xyz="0.0084939436722219902043 -0.00026229267814972812012 -0.0067499976398635638114" rpy="0 0 0"/>
<mass value="0.011864989574403404446" />
<inertia ixx="5.4043476975389825096e-07" ixy="-5.8686598046441902219e-08"  ixz="4.11856729056524649e-14" iyy="1.221237368139783601e-06" iyz="1.4027739154388044693e-13" izz="1.1986582767035206919e-06" />
</inertial>
</link>

<link name="d1-2_urdf">
<visual>
<origin xyz="-0.088875000000000023426 0.038874999999999937383 -0.0062500000000000142247" rpy="-1.5707963267948961139 -8.8739653577863057829e-16 -8.6780554532362652871e-19" />
<geometry>
<mesh filename="meshes/d1-2_urdf.stl"/>
</geometry>
<material name="d1-2_urdf_material">
<color rgba="0.34901960784313723618 0.37647058823529411242 0.4000000000000000222 1.0"/>
</material>
</visual>
<collision>
<origin xyz="-0.088875000000000023426 0.038874999999999937383 -0.0062500000000000142247" rpy="-1.5707963267948961139 -8.8739653577863057829e-16 -8.6780554532362652871e-19" />
<geometry>
<mesh filename="meshes/d1-2_urdf.stl"/>
</geometry>
</collision>
<inertial>
<origin xyz="0.00081610826597225405443 0.0094232453162033935623 -0.0062500231253482434537" rpy="0 0 0"/>
<mass value="0.0096628566425330797429" />
<inertia ixx="8.3693839580018464351e-07" ixy="1.4748701787318253638e-08"  ixz="1.3783262346671661011e-13" iyy="3.1465896345851337052e-07" iyz="2.2310472631912615751e-12" izz="8.3666691222579771062e-07" />
</inertial>
</link>

<joint name="ring_34" type="revolute">
<origin xyz="0.025999999999999967581 7.1015242297800540427e-18 -0.00050000000000000217881" rpy="4.9184194849935814842e-16 5.9160570651602741219e-16 -1.5707963267948952257" />
<parent link="d2-2_urdf" />
<child link="d1-2_urdf" />
<axis xyz="0 0 1"/>
<limit effort="1000" velocity="20" lower="0" upper="1.570796326794896558"/>
<joint_properties friction="0.0"/>
</joint>

<joint name="ring_23" type="revolute">
<origin xyz="-0.0010000000000000008882 -0.037875000000000019762 -0.00049999999999997789268" rpy="4.6419088965683682166e-17 4.5000038854484199404e-15 -1.5707963267948970021" />
<parent link="d3-2_urdf" />
<child link="d2-2_urdf" />
<axis xyz="0 0 1"/>
<limit effort="1000" velocity="20" lower="0" upper="1.570796326794896558"/>
<joint_properties friction="0.0"/>
</joint>

<joint name="ring_12" type="revolute">
<origin xyz="-0.015274999999999983036 0.0072500000000000090414 -0.0077499999999999895361" rpy="-1.5707963267948992225 -1.5707963267948885644 0" />
<parent link="d4-2_urdf" />
<child link="d3-2_urdf" />
<axis xyz="0 0 1"/>
<limit effort="1000" velocity="20" lower="-0.034906585039886590949" upper="1.570796326794896558"/>
<joint_properties friction="0.0"/>
</joint>

<joint name="ring_01" type="revolute">
<origin xyz="-0.011384348636380853259 0.19516197601440887777 0.010513965579231929898" rpy="-0.087000830522749331153 0.0068123514634783575994 -1.5321205940965849646" />
<parent link="right_forearm_and_palm_assembly" />
<child link="d4-2_urdf" />
<axis xyz="0 0 1"/>
<limit effort="1000" velocity="20" lower="-0.29670597283903604735" upper="0.29670597283903604735"/>
<joint_properties friction="0.0"/>
</joint>

<link name="d4-3_urdf">
<visual>
<origin xyz="-0.079149999999999998135 0 -0.0087499999999999990979" rpy="3.141592653589793116 -6.86274516867824596e-36 2.9272904565288895708e-32" />
<geometry>
<mesh filename="meshes/d4-3_urdf.stl"/>
</geometry>
<material name="d4-3_urdf_material">
<color rgba="0.34901960784313723618 0.37647058823529411242 0.4000000000000000222 1.0"/>
</material>
</visual>
<collision>
<origin xyz="-0.079149999999999998135 0 -0.0087499999999999990979" rpy="3.141592653589793116 -6.86274516867824596e-36 2.9272904565288895708e-32" />
<geometry>
<mesh filename="meshes/d4-3_urdf.stl"/>
</geometry>
</collision>
<inertial>
<origin xyz="-0.0062842813664121671691 2.5879353744798092046e-10 -0.0081923602347070724472" rpy="0 0 0"/>
<mass value="0.0071322314487868359797" />
<inertia ixx="4.8911025414963867866e-07" ixy="-2.0479711690979226971e-14"  ixz="1.4355227474224373716e-08" iyy="5.4026894403887874679e-07" iyz="1.5625068491580762688e-13" izz="7.1745332239577878067e-07" />
</inertial>
</link>

<link name="d3-3_urdf">
<visual>
<origin xyz="-0.063875000000000001221 0.0009999999999999731326 -0.0072500000000000463379" rpy="-1.5707963267948976682 -5.8880953492685354486e-16 1.6948183510606307051e-32" />
<geometry>
<mesh filename="meshes/d3-3_urdf.stl"/>
</geometry>
<material name="d3-3_urdf_material">
<color rgba="0.34901960784313723618 0.37647058823529411242 0.4000000000000000222 1.0"/>
</material>
</visual>
<collision>
<origin xyz="-0.063875000000000001221 0.0009999999999999731326 -0.0072500000000000463379" rpy="-1.5707963267948976682 -5.8880953492685354486e-16 1.6948183510606307051e-32" />
<geometry>
<mesh filename="meshes/d3-3_urdf.stl"/>
</geometry>
</collision>
<inertial>
<origin xyz="-0.0006959813154321925488 -0.013461728376310346661 -0.0072499999060333056994" rpy="0 0 0"/>
<mass value="0.022614819883081289931" />
<inertia ixx="4.0178611346720790771e-06" ixy="1.0347442960778401634e-07"  ixz="1.2277342610578212517e-14" iyy="1.3431972486150069921e-06" iyz="-4.2659478106741681693e-14" izz="4.0893383736853514403e-06" />
</inertial>
</link>

<link name="d2-3_urdf">
<visual>
<origin xyz="-0.062874999999999986455 0.038875000000000006772 -0.0067500000000000962008" rpy="-1.57079632679489678 -1.6156388965885127981e-15 -9.2444637330587320947e-32" />
<geometry>
<mesh filename="meshes/d2-3_urdf.stl"/>
</geometry>
<material name="d2-3_urdf_material">
<color rgba="0.34901960784313723618 0.37647058823529411242 0.4000000000000000222 1.0"/>
</material>
</visual>
<collision>
<origin xyz="-0.062874999999999986455 0.038875000000000006772 -0.0067500000000000962008" rpy="-1.57079632679489678 -1.6156388965885127981e-15 -9.2444637330587320947e-32" />
<geometry>
<mesh filename="meshes/d2-3_urdf.stl"/>
</geometry>
</collision>
<inertial>
<origin xyz="0.0084939436722219902043 -0.00026229267814973505901 -0.0067499976398635655461" rpy="0 0 0"/>
<mass value="0.011864989574403404446" />
<inertia ixx="5.4043476975389814508e-07" ixy="-5.8686598046441862515e-08"  ixz="4.1185672854261180908e-14" iyy="1.2212373681397833892e-06" iyz="1.4027739154023800477e-13" izz="1.1986582767035206919e-06" />
</inertial>
</link>

<link name="d1-3_urdf">
<visual>
<origin xyz="-0.088875000000000009548 0.038874999999999992895 -0.00625000000000001249" rpy="-1.5707963267948961139 -8.7170368868848065378e-16 5.8464010874321581202e-32" />
<geometry>
<mesh filename="meshes/d1-3_urdf.stl"/>
</geometry>
<material name="d1-3_urdf_material">
<color rgba="0.34901960784313723618 0.37647058823529411242 0.4000000000000000222 1.0"/>
</material>
</visual>
<collision>
<origin xyz="-0.088875000000000009548 0.038874999999999992895 -0.00625000000000001249" rpy="-1.5707963267948961139 -8.7170368868848065378e-16 5.8464010874321581202e-32" />
<geometry>
<mesh filename="meshes/d1-3_urdf.stl"/>
</geometry>
</collision>
<inertial>
<origin xyz="0.00081610826597226793222 0.0094232453162034490735 -0.0062500231253482443211" rpy="0 0 0"/>
<mass value="0.0096628566425330814776" />
<inertia ixx="8.3693839580018422e-07" ixy="1.4748701787318253638e-08"  ixz="1.3783262349187137752e-13" iyy="3.1465896345851337052e-07" iyz="2.2310472631914635235e-12" izz="8.366669122257972871e-07" />
</inertial>
</link>

<joint name="middle_34" type="revolute">
<origin xyz="0.025999999999999967581 -1.8431436932253575378e-18 -0.00050000000000000044409" rpy="1.374019371753883429e-15 1.010804088085701642e-15 -1.5707963267948958919" />
<parent link="d2-3_urdf" />
<child link="d1-3_urdf" />
<axis xyz="0 0 1"/>
<limit effort="1000" velocity="20" lower="0" upper="1.570796326794896558"/>
<joint_properties friction="0.0"/>
</joint>

<joint name="middle_23" type="revolute">
<origin xyz="-0.00099999999999999655137 -0.037875000000000075273 -0.00049999999999997615796" rpy="1.4009774771081203282e-15 -5.8917067141199026395e-16 -1.5707963267948970021" />
<parent link="d3-3_urdf" />
<child link="d2-3_urdf" />
<axis xyz="0 0 1"/>
<limit effort="1000" velocity="20" lower="0" upper="1.570796326794896558"/>
<joint_properties friction="0.0"/>
</joint>

<joint name="middle_12" type="revolute">
<origin xyz="-0.015274999999999983036 0.0072500000000000116435 -0.0077499999999999808625" rpy="-1.5707963267948941155 -1.5707963267948961139 0" />
<parent link="d4-3_urdf" />
<child link="d3-3_urdf" />
<axis xyz="0 0 1"/>
<limit effort="1000" velocity="20" lower="-0.034906585039886590949" upper="1.570796326794896558"/>
<joint_properties friction="0.0"/>
</joint>

<joint name="middle_01" type="revolute">
<origin xyz="0.012138454601756621873 0.19914999999999996594 0.008000647022553285248" rpy="-1.3866381960025091427e-17 1.1102487805056423062e-16 -1.5707963267948974462" />
<parent link="right_forearm_and_palm_assembly" />
<child link="d4-3_urdf" />
<axis xyz="0 0 1"/>
<limit effort="1000" velocity="20" lower="-0.29670597283903604735" upper="0.29670597283903604735"/>
<joint_properties friction="0.0"/>
</joint>

<link name="d4-4_urdf">
<visual>
<origin xyz="-0.079149999999999970379 0 -0.0087500000000000008327" rpy="-3.141592653589793116 5.6007022281921806211e-20 -6.3438766466273619014e-18" />
<geometry>
<mesh filename="meshes/d4-4_urdf.stl"/>
</geometry>
<material name="d4-4_urdf_material">
<color rgba="0.34901960784313723618 0.37647058823529411242 0.4000000000000000222 1.0"/>
</material>
</visual>
<collision>
<origin xyz="-0.079149999999999970379 0 -0.0087500000000000008327" rpy="-3.141592653589793116 5.6007022281921806211e-20 -6.3438766466273619014e-18" />
<geometry>
<mesh filename="meshes/d4-4_urdf.stl"/>
</geometry>
</collision>
<inertial>
<origin xyz="-0.0062842813664121255357 2.5879353725152909219e-10 -0.0081923602347070741819" rpy="0 0 0"/>
<mass value="0.0071322314487868359797" />
<inertia ixx="4.891102541496389963e-07" ixy="-2.0479711698571391562e-14"  ixz="1.4355227474224375371e-08" iyy="5.4026894403887885267e-07" iyz="1.5625068489769038227e-13" izz="7.1745332239577867479e-07" />
</inertial>
</link>

<link name="d3-4_urdf">
<visual>
<origin xyz="-0.063875000000000001221 0.00099999999999994537703 -0.0072500000000000480727" rpy="-1.5707963267948976682 -5.6991447625920315517e-16 -2.8317947779213194573e-20" />
<geometry>
<mesh filename="meshes/d3-4_urdf.stl"/>
</geometry>
<material name="d3-4_urdf_material">
<color rgba="0.34901960784313723618 0.37647058823529411242 0.4000000000000000222 1.0"/>
</material>
</visual>
<collision>
<origin xyz="-0.063875000000000001221 0.00099999999999994537703 -0.0072500000000000480727" rpy="-1.5707963267948976682 -5.6991447625920315517e-16 -2.8317947779213194573e-20" />
<geometry>
<mesh filename="meshes/d3-4_urdf.stl"/>
</geometry>
</collision>
<inertial>
<origin xyz="-0.0006959813154321925488 -0.013461728376310377886 -0.0072499999060333091688" rpy="0 0 0"/>
<mass value="0.022614819883081289931" />
<inertia ixx="4.0178611346720799241e-06" ixy="1.034744296077839634e-07"  ixz="1.227734251813886371e-14" iyy="1.3431972486150078391e-06" iyz="-4.2659477987127920636e-14" izz="4.0893383736853514403e-06" />
</inertial>
</link>

<link name="d2-4_urdf">
<visual>
<origin xyz="-0.062875000000000014211 0.038875000000000006772 -0.0067500000000000927314" rpy="-1.570796326794896558 -1.6200486936989597183e-15 -6.0967158515017657566e-19" />
<geometry>
<mesh filename="meshes/d2-4_urdf.stl"/>
</geometry>
<material name="d2-4_urdf_material">
<color rgba="0.34901960784313723618 0.37647058823529411242 0.4000000000000000222 1.0"/>
</material>
</visual>
<collision>
<origin xyz="-0.062875000000000014211 0.038875000000000006772 -0.0067500000000000927314" rpy="-1.570796326794896558 -1.6200486936989597183e-15 -6.0967158515017657566e-19" />
<geometry>
<mesh filename="meshes/d2-4_urdf.stl"/>
</geometry>
</collision>
<inertial>
<origin xyz="0.0084939436722219624487 -0.00026229267814974199791 -0.0067499976398635620767" rpy="0 0 0"/>
<mass value="0.011864989574403404446" />
<inertia ixx="5.4043476975389825096e-07" ixy="-5.8686598046441869132e-08"  ixz="4.1185672868915199923e-14" iyy="1.2212373681397840245e-06" iyz="1.4027739154228316137e-13" izz="1.1986582767035206919e-06" />
</inertial>
</link>

<link name="d1-4_urdf">
<visual>
<origin xyz="-0.088875000000000009548 0.038874999999999992895 -0.0062500000000000090206" rpy="-1.5707963267948961139 -8.8289208817102850906e-16 5.7463783702987361212e-19" />
<geometry>
<mesh filename="meshes/d1-4_urdf.stl"/>
</geometry>
<material name="d1-4_urdf_material">
<color rgba="0.34901960784313723618 0.37647058823529411242 0.4000000000000000222 1.0"/>
</material>
</visual>
<collision>
<origin xyz="-0.088875000000000009548 0.038874999999999992895 -0.0062500000000000090206" rpy="-1.5707963267948961139 -8.8289208817102850906e-16 5.7463783702987361212e-19" />
<geometry>
<mesh filename="meshes/d1-4_urdf.stl"/>
</geometry>
</collision>
<inertial>
<origin xyz="0.00081610826597225405443 0.0094232453162034525429 -0.0062500231253482399843" rpy="0 0 0"/>
<mass value="0.0096628566425330814776" />
<inertia ixx="8.3693839580018400824e-07" ixy="1.4748701787318260255e-08"  ixz="1.3783262348972302528e-13" iyy="3.1465896345851337052e-07" iyz="2.2310472631806948274e-12" izz="8.366669122257972871e-07" />
</inertial>
</link>

<joint name="index_34" type="revolute">
<origin xyz="0.025999999999999967581 5.0957502106818708398e-18 -0.0004999999999999935052" rpy="6.9057684691951674976e-15 1.7165371139413334888e-14 -1.5707963267948905628" />
<parent link="d2-4_urdf" />
<child link="d1-4_urdf" />
<axis xyz="0 0 1"/>
<limit effort="1000" velocity="20" lower="0" upper="1.570796326794896558"/>
<joint_properties friction="0.0"/>
</joint>

<joint name="index_23" type="revolute">
<origin xyz="-0.00099999999999998267358 -0.037875000000000047518 -0.00049999999999997962741" rpy="-1.0736478731469521164e-15 -6.4972537115075657867e-15 -1.57079632679489678" />
<parent link="d3-4_urdf" />
<child link="d2-4_urdf" />
<axis xyz="0 0 1"/>
<limit effort="1000" velocity="20" lower="0" upper="1.570796326794896558"/>
<joint_properties friction="0.0"/>
</joint>

<joint name="index_12" type="revolute">
<origin xyz="-0.01527499999999995528 0.0072500000000000133782 -0.0077499999999999860667" rpy="-1.5707963267948941155 -1.570796326794896336 0" />
<parent link="d4-4_urdf" />
<child link="d3-4_urdf" />
<axis xyz="0 0 1"/>
<limit effort="1000" velocity="20" lower="-0.034906585039886590949" upper="1.570796326794896558"/>
<joint_properties friction="0.0"/>
</joint>

<joint name="index_01" type="revolute">
<origin xyz="0.035661257839894433541 0.19513802398559082496 0.010513965579232155412" rpy="0.087266462599716959625 5.9001432083974589266e-17 -1.6100662349647696381" />
<parent link="right_forearm_and_palm_assembly" />
<child link="d4-4_urdf" />
<axis xyz="0 0 1"/>
<limit effort="1000" velocity="20" lower="-0.29670597283903604735" upper="0.29670597283903604735"/>
<joint_properties friction="0.0"/>
</joint>


</robot>
